test_factorial (__main__.TestExercice) ... ERROR
test_prefixes (__main__.TestExercice) ... FAIL
test_summation (__main__.TestExercice) ... ERROR

======================================================================
ERROR: test_factorial (__main__.TestExercice)
----------------------------------------------------------------------
Traceback (most recent call last):
  File "test_exercice.py", line 44, in test_factorial
    output = [exercice.factorial(v) for v in values]
  File "test_exercice.py", line 44, in <listcomp>
    output = [exercice.factorial(v) for v in values]
  File "/home/runner/work/c01_ch5_exercices-simo255/c01_ch5_exercices-simo255/exercice.py", line 32, in factorial
    return math.factorial(number)
NameError: name 'math' is not defined

======================================================================
ERROR: test_summation (__main__.TestExercice)
----------------------------------------------------------------------
Traceback (most recent call last):
  File "test_exercice.py", line 33, in test_summation
    output = exercice.prime_integer_summation()
  File "/home/runner/work/c01_ch5_exercices-simo255/c01_ch5_exercices-simo255/exercice.py", line 23, in prime_integer_summation
    return false
NameError: name 'false' is not defined

======================================================================
FAIL: test_prefixes (__main__.TestExercice)
----------------------------------------------------------------------
Traceback (most recent call last):
  File "test_exercice.py", line 20, in test_prefixes
    'Mauvaise identification de la parit√© de la longueur de la chaine'
AssertionError: First sequence is not a list: 'Jack'

----------------------------------------------------------------------
Ran 3 tests in 0.001s

FAILED (failures=1, errors=2)
